Workbook

Sheet Indicateurs
A1: Intitulé | B1: Id
A2: Proportion de la population vivant en dessous du seuil national de pauvreté | B2: 1246
A3: Incidence de la pauvreté multidimensionnelle | B3: 1247
A4: Espérance de vie à la naissance | B4: 1248
A5: Taux de satisfaction des populations vis-à-vis des services des forces de défense et de sécurité | B5: 1249
A6: Proportion des communes déclarées en état d’urgence | B6: 1250
A7: Proportion des frontières du territoire délimités et abornées (en distance kilométrique) | B7: 1251
A8: Taux de variation des conflits inter et intra-communautaires | B8: 1252
A9: Proportion de comités de Paix opérationnels pour la prévention et la gestion des conflits communautaires | B9: 1253
A10: Proportion de la population estimant que les informations fournies par les autorités centrales sur le budget et les politiques publiques sont suffisantes | B10: 1254
A11: Proportion de la population ayant contribué à au moins une action de développement bénévolement | B11: 1255
A12: Taux de satisfaction des usagers des services judiciaires | B12: 1256
A13: Délai moyen de traitement des affaires pénales | B13: 1257
... A72: Taux de réalisation de logements sociaux | B72: 1316

Sheet Desagregations
A1: Intitulé | B1: Id
A2: Femme | B2: 2
A3: Homme | B3: 1
A4: Urbain | B4: 3
A5: Rural | B5: 5
A6: Total | B6: 6

Sheet Sources
A1: Intitulé | B1: Id
A2: INS, 2021, EHCVM | B2: 4
A3: INS, 2019, Rapport sur les projections démographiques | B3: 5
A4: Rapport Ministère en charge de l'intérieur | B4: 6
A5: Rapport Ministère en charge de l'intérieur 2022 | B5: 7
A6: HACP | B6: 8
A7: MJDH, 2022, Rapport d'enquête sur les besoins et la satisfaction en matière de justice | B7: 9
A8: MJDH | B8: 10
A9: RAP du ministère en charge de la fonction publique | B9: 11
A10: Cour des comptes, 2021, Rapport d'activité | B10: 12
A11: Ministère de l'intérieur | B11: 13
A12: MJCAS | B12: 14
A13: Annuaire MJCAS | B13: 15
... A48: MU/H RAP | B48: 50

Sheet Unites
A1: Intitulé | B1: Id
A2: % | B2: 4
A3: Ans | B3: 5
A4: Jour | B4: 6
A5: Encadrants pour 1000hbts | B5: 7
A6: Nombre | B6: 8
A7: Indice | B7: 9
A8: Km/1000hbts | B8: 10
A9: ‰ | B9: 11
A10: 100 000 naissances | B10: 12
A11: Ratio | B11: 13

Sheet Zones
A1: Intitulé | B1: Id | C1: Niveau
A2: NIGER | B2: 1 | C2: 1
A3: NIAMEY | B3: 2 | C3: 2
A4: DOSSO | B4: 3 | C4: 2
A5: AGADEZ | B5: 4 | C5: 2
A6: TAHOUA | B6: 5 | C6: 2
A7: MARADI | B7: 6 | C7: 2
A8: DIFFA | B8: 7 | C8: 2
A9: VILLE DE NIAMEY | B9: 8 | C9: 3
A10: DOGONDOUTCHI | B10: 9 | C10: 3
A11: INGALL | B11: 10 | C11: 3
A12: TAHOUA | B12: 11 | C12: 3
A13: BAGAROUA | B13: 13 | C13: 3
... A320: MAKALONDI | B320: 333 | C320: 4

Sheet Periodes
A1: Intitulé | B1: Id
A2: 2000 | B2: 1
A3: 2001 | B3: 2
A4: 2002 | B4: 3
A5: 2003 | B5: 4
A6: 2004 | B6: 5
A7: 2005 | B7: 6
A8: 2006 | B8: 7
A9: 2007 | B9: 8
A10: 2008 | B10: 9
A11: 2009 | B11: 10
A12: 2010 | B12: 11
A13: 2011 | B13: 12
... A32: 2030 | B32: 31

Sheet CommentaireValeurIndicateurs
A1: Intitulé | B1: Id
A2: ... | B2: 2
A3: /// | B3: 1
A4: RAS | B4: 3

Sheet NatureDonnees
A1: Intitulé | B1: Id
A2: Prévision | B2: 1
A3: Réalisation | B3: 2
A4: Valeur de référence | B4: 3

Sheet Data
A1: Code | B1: Indicateur | C1: Zone | D1: Unite | E1: Source | F1: CommentaireValeur | G1: NatureDonnee | H1: Periode | I1: valeur | K1: Début Désagregation
A2: 1246-1-6-4-4-3-3-22 | B2: Proportion de la population vivant en dessous du seuil national de pauvreté | C2: NIGER | D2: % | E2: INS, 2021, EHCVM | F2: RAS | G2: Valeur de référence | H2: 2021 | I2: 41.2 | K2: Total
A3: 1247-1-6-4-4-3-3-22 | B3: Incidence de la pauvreté multidimensionnelle | C3: NIGER | D3: % | E3: INS, 2021, EHCVM | F3: RAS | G3: Valeur de référence | H3: 2021 | I3: 71.5 | K3: Total
A4: 1248-1-6-5-5-3-3-24 | B4: Espérance de vie à la naissance | C4: NIGER | D4: Ans | E4: INS, 2019, Rapport sur les projections démographiques | F4: RAS | G4: Valeur de référence | H4: 2023 | I4: 65.9 | K4: Total
A5: 1249-1-6-4-4-3-3-22 | B5: Taux de satisfaction des populations vis-à-vis des services des forces de défense et de sécurité | C5: NIGER | D5: % | E5: INS, 2021, EHCVM | F5: RAS | G5: Valeur de référence | H5: 2021 | I5: 79.2 | K5: Total
A6: 1250-1-6-4-6-3-3-25 | B6: Proportion des communes déclarées en état d’urgence | C6: NIGER | D6: % | E6: Rapport Ministère en charge de l'intérieur | F6: RAS | G6: Valeur de référence | H6: 2024 | I6: 20.3 | K6: Total
A7: 1251-1-6-4-7-3-3-23 | B7: Proportion des frontières du territoire délimités et abornées (en distance kilométrique) | C7: NIGER | D7: % | E7: Rapport Ministère en charge de l'intérieur 2022 | F7: RAS | G7: Valeur de référence | H7: 2022 | I7: 50.37 | K7: Total
A8: 1252-1-6-4-8-3-3-24 | B8: Taux de variation des conflits inter et intra-communautaires | C8: NIGER | D8: % | E8: HACP | F8: RAS | G8: Valeur de référence | H8: 2023 | I8: 35.95 | K8: Total
A9: 1253-1-6-4-8-3-3-24 | B9: Proportion de comités de Paix opérationnels pour la prévention et la gestion des conflits communautaires | C9: NIGER | D9: % | E9: HACP | F9: RAS | G9: Valeur de référence | H9: 2023 | I9: 18.04 | K9: Total
A10: 1254-1-6-4-4-3-3-22 | B10: Proportion de la population estimant que les informations fournies par les autorités centrales sur le budget et les politiques publiques sont suffisantes | C10: NIGER | D10: % | E10: INS, 2021, EHCVM | F10: RAS | G10: Valeur de référence | H10: 2021 | I10: 9.3 | K10: Total
A11: 1255-1-6-4-4-3-3-22 | B11: Proportion de la population ayant contribué à au moins une action de développement bénévolement | C11: NIGER | D11: % | E11: INS, 2021, EHCVM | F11: RAS | G11: Valeur de référence | H11: 2021 | I11: 60.4 | K11: Total
A12: 1256-1-6-4-9-3-3-23 | B12: Taux de satisfaction des usagers des services judiciaires | C12: NIGER | D12: % | E12: MJDH, 2022, Rapport d'enquête sur les besoins et la satisfaction en matière de justice | F12: RAS | G12: Valeur de référence | H12: 2022 | I12: 74.4 | K12: Total
A13: 1257-1-6-6-10-3-3-24 | B13: Délai moyen de traitement des affaires pénales | C13: NIGER | D13: Jour | E13: MJDH | F13: RAS | G13: Valeur de référence | H13: 2023 | I13: 19 | K13: Total
... A69: 1316-1-6-4-50-3-3-24 | B69: Taux de réalisation de logements sociaux | C69: NIGER | D69: % | E69: MU/H RAP | F69: RAS | G69: Valeur de référence | H69: 2023 | I69: 11.05 | K69: Total

Sheet bkp
A1: Code | B1: Indicateur | C1: Zone | D1: Unite | E1: Source | F1: CommentaireValeur | G1: NatureDonnee | H1: Periode | I1: valeur | K1: Début Désagregation
A2: =_xlfn.CONCAT(VLOOKUP(B2,Indicateurs!$A:$B,2,0),"-",VLOOKUP(C2,Zones!$A:$B,2,0),"-",_xlfn.CONCAT(IF(K2<>"",VLOOKUP(K2,Desagregations!$A:$B,2,0),""),IF(L2<>"","_",""),IF(L2<>"",VLOOKUP(L2,Desagregations!$A:$B,2,0),""),IF(M2<>"","_",""),IF(M2<>"",VLOOKUP(M2,Desagregations!$A:$B,2,0),""),IF(N2<>"","_",""),IF(N2<>"",VLOOKUP(N2,Desagregations!$A:$B,2,0),""),IF(O2<>"","_",""),IF(O2<>"",VLOOKUP(O2,Desagregations!$A:$B,2,0),""),IF(P2<>"","_",""),IF(P2<>"",VLOOKUP(P2,Desagregations!$A:$B,2,0),"")),"-",VLOOKUP(D2,Unites!$A:$B,2,0),"-",VLOOKUP(E2,Sources!$A:$B,2,0),"-",VLOOKUP(F2,CommentaireValeurIndicateurs!$A:$B,2,0),"-",VLOOKUP(G2,NatureDonnees!$A:$B,2,0),"-",VLOOKUP(H2,Periodes!$A:$B,2,0)) -> 1246-1-6-4-4-3-3-22 | B2: Proportion de la population vivant en dessous du seuil national de pauvreté | C2: NIGER | D2: % | E2: INS, 2021, EHCVM | F2: RAS | G2: Valeur de référence | H2: 2021 | I2: 41.2 | K2: Total
A3: =_xlfn.CONCAT(VLOOKUP(B3,Indicateurs!$A:$B,2,0),"-",VLOOKUP(C3,Zones!$A:$B,2,0),"-",_xlfn.CONCAT(IF(K3<>"",VLOOKUP(K3,Desagregations!$A:$B,2,0),""),IF(L3<>"","_",""),IF(L3<>"",VLOOKUP(L3,Desagregations!$A:$B,2,0),""),IF(M3<>"","_",""),IF(M3<>"",VLOOKUP(M3,Desagregations!$A:$B,2,0),""),IF(N3<>"","_",""),IF(N3<>"",VLOOKUP(N3,Desagregations!$A:$B,2,0),""),IF(O3<>"","_",""),IF(O3<>"",VLOOKUP(O3,Desagregations!$A:$B,2,0),""),IF(P3<>"","_",""),IF(P3<>"",VLOOKUP(P3,Desagregations!$A:$B,2,0),"")),"-",VLOOKUP(D3,Unites!$A:$B,2,0),"-",VLOOKUP(E3,Sources!$A:$B,2,0),"-",VLOOKUP(F3,CommentaireValeurIndicateurs!$A:$B,2,0),"-",VLOOKUP(G3,NatureDonnees!$A:$B,2,0),"-",VLOOKUP(H3,Periodes!$A:$B,2,0)) -> 1247-1-6-4-4-3-3-22 | B3: Incidence de la pauvreté multidimensionnelle | C3: NIGER | D3: % | E3: INS, 2021, EHCVM | F3: RAS | G3: Valeur de référence | H3: 2021 | I3: 71.5 | K3: Total
A4: =_xlfn.CONCAT(VLOOKUP(B4,Indicateurs!$A:$B,2,0),"-",VLOOKUP(C4,Zones!$A:$B,2,0),"-",_xlfn.CONCAT(IF(K4<>"",VLOOKUP(K4,Desagregations!$A:$B,2,0),""),IF(L4<>"","_",""),IF(L4<>"",VLOOKUP(L4,Desagregations!$A:$B,2,0),""),IF(M4<>"","_",""),IF(M4<>"",VLOOKUP(M4,Desagregations!$A:$B,2,0),""),IF(N4<>"","_",""),IF(N4<>"",VLOOKUP(N4,Desagregations!$A:$B,2,0),""),IF(O4<>"","_",""),IF(O4<>"",VLOOKUP(O4,Desagregations!$A:$B,2,0),""),IF(P4<>"","_",""),IF(P4<>"",VLOOKUP(P4,Desagregations!$A:$B,2,0),"")),"-",VLOOKUP(D4,Unites!$A:$B,2,0),"-",VLOOKUP(E4,Sources!$A:$B,2,0),"-",VLOOKUP(F4,CommentaireValeurIndicateurs!$A:$B,2,0),"-",VLOOKUP(G4,NatureDonnees!$A:$B,2,0),"-",VLOOKUP(H4,Periodes!$A:$B,2,0)) -> 1248-1-6-5-5-3-3-24 | B4: Espérance de vie à la naissance | C4: NIGER | D4: Ans | E4: INS, 2019, Rapport sur les projections démographiques | F4: RAS | G4: Valeur de référence | H4: 2023 | I4: 65.9 | K4: Total
A5: =_xlfn.CONCAT(VLOOKUP(B5,Indicateurs!$A:$B,2,0),"-",VLOOKUP(C5,Zones!$A:$B,2,0),"-",_xlfn.CONCAT(IF(K5<>"",VLOOKUP(K5,Desagregations!$A:$B,2,0),""),IF(L5<>"","_",""),IF(L5<>"",VLOOKUP(L5,Desagregations!$A:$B,2,0),""),IF(M5<>"","_",""),IF(M5<>"",VLOOKUP(M5,Desagregations!$A:$B,2,0),""),IF(N5<>"","_",""),IF(N5<>"",VLOOKUP(N5,Desagregations!$A:$B,2,0),""),IF(O5<>"","_",""),IF(O5<>"",VLOOKUP(O5,Desagregations!$A:$B,2,0),""),IF(P5<>"","_",""),IF(P5<>"",VLOOKUP(P5,Desagregations!$A:$B,2,0),"")),"-",VLOOKUP(D5,Unites!$A:$B,2,0),"-",VLOOKUP(E5,Sources!$A:$B,2,0),"-",VLOOKUP(F5,CommentaireValeurIndicateurs!$A:$B,2,0),"-",VLOOKUP(G5,NatureDonnees!$A:$B,2,0),"-",VLOOKUP(H5,Periodes!$A:$B,2,0)) -> 1249-1-6-4-4-3-3-22 | B5: Taux de satisfaction des populations vis-à-vis des services des forces de défense et de sécurité | C5: NIGER | D5: % | E5: INS, 2021, EHCVM | F5: RAS | G5: Valeur de référence | H5: 2021 | I5: 79.2 | K5: Total
A6: =_xlfn.CONCAT(VLOOKUP(B6,Indicateurs!$A:$B,2,0),"-",VLOOKUP(C6,Zones!$A:$B,2,0),"-",_xlfn.CONCAT(IF(K6<>"",VLOOKUP(K6,Desagregations!$A:$B,2,0),""),IF(L6<>"","_",""),IF(L6<>"",VLOOKUP(L6,Desagregations!$A:$B,2,0),""),IF(M6<>"","_",""),IF(M6<>"",VLOOKUP(M6,Desagregations!$A:$B,2,0),""),IF(N6<>"","_",""),IF(N6<>"",VLOOKUP(N6,Desagregations!$A:$B,2,0),""),IF(O6<>"","_",""),IF(O6<>"",VLOOKUP(O6,Desagregations!$A:$B,2,0),""),IF(P6<>"","_",""),IF(P6<>"",VLOOKUP(P6,Desagregations!$A:$B,2,0),"")),"-",VLOOKUP(D6,Unites!$A:$B,2,0),"-",VLOOKUP(E6,Sources!$A:$B,2,0),"-",VLOOKUP(F6,CommentaireValeurIndicateurs!$A:$B,2,0),"-",VLOOKUP(G6,NatureDonnees!$A:$B,2,0),"-",VLOOKUP(H6,Periodes!$A:$B,2,0)) -> 1250-1-6-4-6-3-3-25 | B6: Proportion des communes déclarées en état d’urgence | C6: NIGER | D6: % | E6: Rapport Ministère en charge de l'intérieur | F6: RAS | G6: Valeur de référence | H6: 2024 | I6: 20.3 | K6: Total
A7: =_xlfn.CONCAT(VLOOKUP(B7,Indicateurs!$A:$B,2,0),"-",VLOOKUP(C7,Zones!$A:$B,2,0),"-",_xlfn.CONCAT(IF(K7<>"",VLOOKUP(K7,Desagregations!$A:$B,2,0),""),IF(L7<>"","_",""),IF(L7<>"",VLOOKUP(L7,Desagregations!$A:$B,2,0),""),IF(M7<>"","_",""),IF(M7<>"",VLOOKUP(M7,Desagregations!$A:$B,2,0),""),IF(N7<>"","_",""),IF(N7<>"",VLOOKUP(N7,Desagregations!$A:$B,2,0),""),IF(O7<>"","_",""),IF(O7<>"",VLOOKUP(O7,Desagregations!$A:$B,2,0),""),IF(P7<>"","_",""),IF(P7<>"",VLOOKUP(P7,Desagregations!$A:$B,2,0),"")),"-",VLOOKUP(D7,Unites!$A:$B,2,0),"-",VLOOKUP(E7,Sources!$A:$B,2,0),"-",VLOOKUP(F7,CommentaireValeurIndicateurs!$A:$B,2,0),"-",VLOOKUP(G7,NatureDonnees!$A:$B,2,0),"-",VLOOKUP(H7,Periodes!$A:$B,2,0)) -> 1251-1-6-4-7-3-3-23 | B7: Proportion des frontières du territoire délimités et abornées (en distance kilométrique) | C7: NIGER | D7: % | E7: Rapport Ministère en charge de l'intérieur 2022 | F7: RAS | G7: Valeur de référence | H7: 2022 | I7: 50.37 | K7: Total
A8: =_xlfn.CONCAT(VLOOKUP(B8,Indicateurs!$A:$B,2,0),"-",VLOOKUP(C8,Zones!$A:$B,2,0),"-",_xlfn.CONCAT(IF(K8<>"",VLOOKUP(K8,Desagregations!$A:$B,2,0),""),IF(L8<>"","_",""),IF(L8<>"",VLOOKUP(L8,Desagregations!$A:$B,2,0),""),IF(M8<>"","_",""),IF(M8<>"",VLOOKUP(M8,Desagregations!$A:$B,2,0),""),IF(N8<>"","_",""),IF(N8<>"",VLOOKUP(N8,Desagregations!$A:$B,2,0),""),IF(O8<>"","_",""),IF(O8<>"",VLOOKUP(O8,Desagregations!$A:$B,2,0),""),IF(P8<>"","_",""),IF(P8<>"",VLOOKUP(P8,Desagregations!$A:$B,2,0),"")),"-",VLOOKUP(D8,Unites!$A:$B,2,0),"-",VLOOKUP(E8,Sources!$A:$B,2,0),"-",VLOOKUP(F8,CommentaireValeurIndicateurs!$A:$B,2,0),"-",VLOOKUP(G8,NatureDonnees!$A:$B,2,0),"-",VLOOKUP(H8,Periodes!$A:$B,2,0)) -> 1252-1-6-4-8-3-3-24 | B8: Taux de variation des conflits inter et intra-communautaires | C8: NIGER | D8: % | E8: HACP | F8: RAS | G8: Valeur de référence | H8: 2023 | I8: 35.95 | K8: Total
A9: =_xlfn.CONCAT(VLOOKUP(B9,Indicateurs!$A:$B,2,0),"-",VLOOKUP(C9,Zones!$A:$B,2,0),"-",_xlfn.CONCAT(IF(K9<>"",VLOOKUP(K9,Desagregations!$A:$B,2,0),""),IF(L9<>"","_",""),IF(L9<>"",VLOOKUP(L9,Desagregations!$A:$B,2,0),""),IF(M9<>"","_",""),IF(M9<>"",VLOOKUP(M9,Desagregations!$A:$B,2,0),""),IF(N9<>"","_",""),IF(N9<>"",VLOOKUP(N9,Desagregations!$A:$B,2,0),""),IF(O9<>"","_",""),IF(O9<>"",VLOOKUP(O9,Desagregations!$A:$B,2,0),""),IF(P9<>"","_",""),IF(P9<>"",VLOOKUP(P9,Desagregations!$A:$B,2,0),"")),"-",VLOOKUP(D9,Unites!$A:$B,2,0),"-",VLOOKUP(E9,Sources!$A:$B,2,0),"-",VLOOKUP(F9,CommentaireValeurIndicateurs!$A:$B,2,0),"-",VLOOKUP(G9,NatureDonnees!$A:$B,2,0),"-",VLOOKUP(H9,Periodes!$A:$B,2,0)) -> 1253-1-6-4-8-3-3-24 | B9: Proportion de comités de Paix opérationnels pour la prévention et la gestion des conflits communautaires | C9: NIGER | D9: % | E9: HACP | F9: RAS | G9: Valeur de référence | H9: 2023 | I9: 18.04 | K9: Total
A10: =_xlfn.CONCAT(VLOOKUP(B10,Indicateurs!$A:$B,2,0),"-",VLOOKUP(C10,Zones!$A:$B,2,0),"-",_xlfn.CONCAT(IF(K10<>"",VLOOKUP(K10,Desagregations!$A:$B,2,0),""),IF(L10<>"","_",""),IF(L10<>"",VLOOKUP(L10,Desagregations!$A:$B,2,0),""),IF(M10<>"","_",""),IF(M10<>"",VLOOKUP(M10,Desagregations!$A:$B,2,0),""),IF(N10<>"","_",""),IF(N10<>"",VLOOKUP(N10,Desagregations!$A:$B,2,0),""),IF(O10<>"","_",""),IF(O10<>"",VLOOKUP(O10,Desagregations!$A:$B,2,0),""),IF(P10<>"","_",""),IF(P10<>"",VLOOKUP(P10,Desagregations!$A:$B,2,0),"")),"-",VLOOKUP(D10,Unites!$A:$B,2,0),"-",VLOOKUP(E10,Sources!$A:$B,2,0),"-",VLOOKUP(F10,CommentaireValeurIndicateurs!$A:$B,2,0),"-",VLOOKUP(G10,NatureDonnees!$A:$B,2,0),"-",VLOOKUP(H10,Periodes!$A:$B,2,0)) -> 1254-1-6-4-4-3-3-22 | B10: Proportion de la population estimant que les informations fournies par les autorités centrales sur le budget et les politiques publiques sont suffisantes | C10: NIGER | D10: % | E10: INS, 2021, EHCVM | F10: RAS | G10: Valeur de référence | H10: 2021 | I10: 9.3 | K10: Total
A11: =_xlfn.CONCAT(VLOOKUP(B11,Indicateurs!$A:$B,2,0),"-",VLOOKUP(C11,Zones!$A:$B,2,0),"-",_xlfn.CONCAT(IF(K11<>"",VLOOKUP(K11,Desagregations!$A:$B,2,0),""),IF(L11<>"","_",""),IF(L11<>"",VLOOKUP(L11,Desagregations!$A:$B,2,0),""),IF(M11<>"","_",""),IF(M11<>"",VLOOKUP(M11,Desagregations!$A:$B,2,0),""),IF(N11<>"","_",""),IF(N11<>"",VLOOKUP(N11,Desagregations!$A:$B,2,0),""),IF(O11<>"","_",""),IF(O11<>"",VLOOKUP(O11,Desagregations!$A:$B,2,0),""),IF(P11<>"","_",""),IF(P11<>"",VLOOKUP(P11,Desagregations!$A:$B,2,0),"")),"-",VLOOKUP(D11,Unites!$A:$B,2,0),"-",VLOOKUP(E11,Sources!$A:$B,2,0),"-",VLOOKUP(F11,CommentaireValeurIndicateurs!$A:$B,2,0),"-",VLOOKUP(G11,NatureDonnees!$A:$B,2,0),"-",VLOOKUP(H11,Periodes!$A:$B,2,0)) -> 1255-1-6-4-4-3-3-22 | B11: Proportion de la population ayant contribué à au moins une action de développement bénévolement | C11: NIGER | D11: % | E11: INS, 2021, EHCVM | F11: RAS | G11: Valeur de référence | H11: 2021 | I11: 60.4 | K11: Total
A12: =_xlfn.CONCAT(VLOOKUP(B12,Indicateurs!$A:$B,2,0),"-",VLOOKUP(C12,Zones!$A:$B,2,0),"-",_xlfn.CONCAT(IF(K12<>"",VLOOKUP(K12,Desagregations!$A:$B,2,0),""),IF(L12<>"","_",""),IF(L12<>"",VLOOKUP(L12,Desagregations!$A:$B,2,0),""),IF(M12<>"","_",""),IF(M12<>"",VLOOKUP(M12,Desagregations!$A:$B,2,0),""),IF(N12<>"","_",""),IF(N12<>"",VLOOKUP(N12,Desagregations!$A:$B,2,0),""),IF(O12<>"","_",""),IF(O12<>"",VLOOKUP(O12,Desagregations!$A:$B,2,0),""),IF(P12<>"","_",""),IF(P12<>"",VLOOKUP(P12,Desagregations!$A:$B,2,0),"")),"-",VLOOKUP(D12,Unites!$A:$B,2,0),"-",VLOOKUP(E12,Sources!$A:$B,2,0),"-",VLOOKUP(F12,CommentaireValeurIndicateurs!$A:$B,2,0),"-",VLOOKUP(G12,NatureDonnees!$A:$B,2,0),"-",VLOOKUP(H12,Periodes!$A:$B,2,0)) -> 1256-1-6-4-9-3-3-23 | B12: Taux de satisfaction des usagers des services judiciaires | C12: NIGER | D12: % | E12: MJDH, 2022, Rapport d'enquête sur les besoins et la satisfaction en matière de justice | F12: RAS | G12: Valeur de référence | H12: 2022 | I12: 74.4 | K12: Total
A13: =_xlfn.CONCAT(VLOOKUP(B13,Indicateurs!$A:$B,2,0),"-",VLOOKUP(C13,Zones!$A:$B,2,0),"-",_xlfn.CONCAT(IF(K13<>"",VLOOKUP(K13,Desagregations!$A:$B,2,0),""),IF(L13<>"","_",""),IF(L13<>"",VLOOKUP(L13,Desagregations!$A:$B,2,0),""),IF(M13<>"","_",""),IF(M13<>"",VLOOKUP(M13,Desagregations!$A:$B,2,0),""),IF(N13<>"","_",""),IF(N13<>"",VLOOKUP(N13,Desagregations!$A:$B,2,0),""),IF(O13<>"","_",""),IF(O13<>"",VLOOKUP(O13,Desagregations!$A:$B,2,0),""),IF(P13<>"","_",""),IF(P13<>"",VLOOKUP(P13,Desagregations!$A:$B,2,0),"")),"-",VLOOKUP(D13,Unites!$A:$B,2,0),"-",VLOOKUP(E13,Sources!$A:$B,2,0),"-",VLOOKUP(F13,CommentaireValeurIndicateurs!$A:$B,2,0),"-",VLOOKUP(G13,NatureDonnees!$A:$B,2,0),"-",VLOOKUP(H13,Periodes!$A:$B,2,0)) -> 1257-1-6-6-10-3-3-24 | B13: Délai moyen de traitement des affaires pénales | C13: NIGER | D13: Jour | E13: MJDH | F13: RAS | G13: Valeur de référence | H13: 2023 | I13: 19 | K13: Total
... A27: =_xlfn.CONCAT(VLOOKUP(B27,Indicateurs!$A:$B,2,0),"-",VLOOKUP(C27,Zones!$A:$B,2,0),"-",_xlfn.CONCAT(IF(K27<>"",VLOOKUP(K27,Desagregations!$A:$B,2,0),""),IF(L27<>"","_",""),IF(L27<>"",VLOOKUP(L27,Desagregations!$A:$B,2,0),""),IF(M27<>"","_",""),IF(M27<>"",VLOOKUP(M27,Desagregations!$A:$B,2,0),""),IF(N27<>"","_",""),IF(N27<>"",VLOOKUP(N27,Desagregations!$A:$B,2,0),""),IF(O27<>"","_",""),IF(O27<>"",VLOOKUP(O27,Desagregations!$A:$B,2,0),""),IF(P27<>"","_",""),IF(P27<>"",VLOOKUP(P27,Desagregations!$A:$B,2,0),"")),"-",VLOOKUP(D27,Unites!$A:$B,2,0),"-",VLOOKUP(E27,Sources!$A:$B,2,0),"-",VLOOKUP(F27,CommentaireValeurIndicateurs!$A:$B,2,0),"-",VLOOKUP(G27,NatureDonnees!$A:$B,2,0),"-",VLOOKUP(H27,Periodes!$A:$B,2,0)) -> 1271-1-6-4-19-3-3-25 | B27: Taux de pression fiscale | C27: NIGER | D27: % | E27: MEF | F27: RAS | G27: Valeur de référence | H27: 2024 | I27: 7 | K27: Total
A28: =_xlfn.CONCAT(VLOOKUP(B28,Indicateurs!$A:$B,2,0),"-",VLOOKUP(C28,Zones!$A:$B,2,0),"-",_xlfn.CONCAT(IF(K28<>"",VLOOKUP(K28,Desagregations!$A:$B,2,0),""),IF(L28<>"","_",""),IF(L28<>"",VLOOKUP(L28,Desagregations!$A:$B,2,0),""),IF(M28<>"","_",""),IF(M28<>"",VLOOKUP(M28,Desagregations!$A:$B,2,0),""),IF(N28<>"","_",""),IF(N28<>"",VLOOKUP(N28,Desagregations!$A:$B,2,0),""),IF(O28<>"","_",""),IF(O28<>"",VLOOKUP(O28,Desagregations!$A:$B,2,0),""),IF(P28<>"","_",""),IF(P28<>"",VLOOKUP(P28,Desagregations!$A:$B,2,0),"")),"-",VLOOKUP(D28,Unites!$A:$B,2,0),"-",VLOOKUP(E28,Sources!$A:$B,2,0),"-",VLOOKUP(F28,CommentaireValeurIndicateurs!$A:$B,2,0),"-",VLOOKUP(G28,NatureDonnees!$A:$B,2,0),"-",VLOOKUP(H28,Periodes!$A:$B,2,0)) -> #N/A | B28: Part des ressources extérieures dans le budget national | C28: NIGER | D28: % | E28: DGB | F28: RAS | G28: Valeur de référence | K28: Total
A29: =_xlfn.CONCAT(VLOOKUP(B29,Indicateurs!$A:$B,2,0),"-",VLOOKUP(C29,Zones!$A:$B,2,0),"-",_xlfn.CONCAT(IF(K29<>"",VLOOKUP(K29,Desagregations!$A:$B,2,0),""),IF(L29<>"","_",""),IF(L29<>"",VLOOKUP(L29,Desagregations!$A:$B,2,0),""),IF(M29<>"","_",""),IF(M29<>"",VLOOKUP(M29,Desagregations!$A:$B,2,0),""),IF(N29<>"","_",""),IF(N29<>"",VLOOKUP(N29,Desagregations!$A:$B,2,0),""),IF(O29<>"","_",""),IF(O29<>"",VLOOKUP(O29,Desagregations!$A:$B,2,0),""),IF(P29<>"","_",""),IF(P29<>"",VLOOKUP(P29,Desagregations!$A:$B,2,0),"")),"-",VLOOKUP(D29,Unites!$A:$B,2,0),"-",VLOOKUP(E29,Sources!$A:$B,2,0),"-",VLOOKUP(F29,CommentaireValeurIndicateurs!$A:$B,2,0),"-",VLOOKUP(G29,NatureDonnees!$A:$B,2,0),"-",VLOOKUP(H29,Periodes!$A:$B,2,0)) -> 1273-1-6-4-21-3-3-24 | B29: Part de quantité de céréales importées par rapport aux besoins | C29: NIGER | D29: % | E29: Ministère de l'Agriculture et l'Elevage | F29: RAS | G29: Valeur de référence | H29: 2023 | I29: 11.7 | K29: Total
A30: =_xlfn.CONCAT(VLOOKUP(B30,Indicateurs!$A:$B,2,0),"-",VLOOKUP(C30,Zones!$A:$B,2,0),"-",_xlfn.CONCAT(IF(K30<>"",VLOOKUP(K30,Desagregations!$A:$B,2,0),""),IF(L30<>"","_",""),IF(L30<>"",VLOOKUP(L30,Desagregations!$A:$B,2,0),""),IF(M30<>"","_",""),IF(M30<>"",VLOOKUP(M30,Desagregations!$A:$B,2,0),""),IF(N30<>"","_",""),IF(N30<>"",VLOOKUP(N30,Desagregations!$A:$B,2,0),""),IF(O30<>"","_",""),IF(O30<>"",VLOOKUP(O30,Desagregations!$A:$B,2,0),""),IF(P30<>"","_",""),IF(P30<>"",VLOOKUP(P30,Desagregations!$A:$B,2,0),"")),"-",VLOOKUP(D30,Unites!$A:$B,2,0),"-",VLOOKUP(E30,Sources!$A:$B,2,0),"-",VLOOKUP(F30,CommentaireValeurIndicateurs!$A:$B,2,0),"-",VLOOKUP(G30,NatureDonnees!$A:$B,2,0),"-",VLOOKUP(H30,Periodes!$A:$B,2,0)) -> 1274-1-6-4-16-3-3-25 | B30: Part de l'agriculture dans le PIB | C30: NIGER | D30: % | E30: INS, 2024, comptes nationaux annuels (CNA) révisés 2015-2022 et provisoires 2023-2024 | F30: RAS | G30: Valeur de référence | H30: 2024 | I30: 26.45 | K30: Total
A31: =_xlfn.CONCAT(VLOOKUP(B31,Indicateurs!$A:$B,2,0),"-",VLOOKUP(C31,Zones!$A:$B,2,0),"-",_xlfn.CONCAT(IF(K31<>"",VLOOKUP(K31,Desagregations!$A:$B,2,0),""),IF(L31<>"","_",""),IF(L31<>"",VLOOKUP(L31,Desagregations!$A:$B,2,0),""),IF(M31<>"","_",""),IF(M31<>"",VLOOKUP(M31,Desagregations!$A:$B,2,0),""),IF(N31<>"","_",""),IF(N31<>"",VLOOKUP(N31,Desagregations!$A:$B,2,0),""),IF(O31<>"","_",""),IF(O31<>"",VLOOKUP(O31,Desagregations!$A:$B,2,0),""),IF(P31<>"","_",""),IF(P31<>"",VLOOKUP(P31,Desagregations!$A:$B,2,0),"")),"-",VLOOKUP(D31,Unites!$A:$B,2,0),"-",VLOOKUP(E31,Sources!$A:$B,2,0),"-",VLOOKUP(F31,CommentaireValeurIndicateurs!$A:$B,2,0),"-",VLOOKUP(G31,NatureDonnees!$A:$B,2,0),"-",VLOOKUP(H31,Periodes!$A:$B,2,0)) -> 1275-1-6-4-22-3-3-23 | B31: Part de la production des cultures irriguées dans la production agricole | C31: NIGER | D31: % | E31: Rapport DS/MAG/EL, RAP et RAC du MAG/EL | F31: RAS | G31: Valeur de référence | H31: 2022 | I31: 37 | K31: Total
A32: =_xlfn.CONCAT(VLOOKUP(B32,Indicateurs!$A:$B,2,0),"-",VLOOKUP(C32,Zones!$A:$B,2,0),"-",_xlfn.CONCAT(IF(K32<>"",VLOOKUP(K32,Desagregations!$A:$B,2,0),""),IF(L32<>"","_",""),IF(L32<>"",VLOOKUP(L32,Desagregations!$A:$B,2,0),""),IF(M32<>"","_",""),IF(M32<>"",VLOOKUP(M32,Desagregations!$A:$B,2,0),""),IF(N32<>"","_",""),IF(N32<>"",VLOOKUP(N32,Desagregations!$A:$B,2,0),""),IF(O32<>"","_",""),IF(O32<>"",VLOOKUP(O32,Desagregations!$A:$B,2,0),""),IF(P32<>"","_",""),IF(P32<>"",VLOOKUP(P32,Desagregations!$A:$B,2,0),"")),"-",VLOOKUP(D32,Unites!$A:$B,2,0),"-",VLOOKUP(E32,Sources!$A:$B,2,0),"-",VLOOKUP(F32,CommentaireValeurIndicateurs!$A:$B,2,0),"-",VLOOKUP(G32,NatureDonnees!$A:$B,2,0),"-",VLOOKUP(H32,Periodes!$A:$B,2,0)) -> 1276-1-6-4-22-3-3-25 | B32: Taux d’accroissement des productions des cultures irriguées | C32: NIGER | D32: % | E32: Rapport DS/MAG/EL, RAP et RAC du MAG/EL | F32: RAS | G32: Valeur de référence | H32: 2024 | I32: 13.35 | K32: Total
A33: =_xlfn.CONCAT(VLOOKUP(B33,Indicateurs!$A:$B,2,0),"-",VLOOKUP(C33,Zones!$A:$B,2,0),"-",_xlfn.CONCAT(IF(K33<>"",VLOOKUP(K33,Desagregations!$A:$B,2,0),""),IF(L33<>"","_",""),IF(L33<>"",VLOOKUP(L33,Desagregations!$A:$B,2,0),""),IF(M33<>"","_",""),IF(M33<>"",VLOOKUP(M33,Desagregations!$A:$B,2,0),""),IF(N33<>"","_",""),IF(N33<>"",VLOOKUP(N33,Desagregations!$A:$B,2,0),""),IF(O33<>"","_",""),IF(O33<>"",VLOOKUP(O33,Desagregations!$A:$B,2,0),""),IF(P33<>"","_",""),IF(P33<>"",VLOOKUP(P33,Desagregations!$A:$B,2,0),"")),"-",VLOOKUP(D33,Unites!$A:$B,2,0),"-",VLOOKUP(E33,Sources!$A:$B,2,0),"-",VLOOKUP(F33,CommentaireValeurIndicateurs!$A:$B,2,0),"-",VLOOKUP(G33,NatureDonnees!$A:$B,2,0),"-",VLOOKUP(H33,Periodes!$A:$B,2,0)) -> 1277-1-6-4-22-3-3-25 | B33: Taux d’accroissement des productions des cultures pluviales | C33: NIGER | D33: % | E33: Rapport DS/MAG/EL, RAP et RAC du MAG/EL | F33: RAS | G33: Valeur de référence | H33: 2024 | I33: 18 | K33: Total
A34: =_xlfn.CONCAT(VLOOKUP(B34,Indicateurs!$A:$B,2,0),"-",VLOOKUP(C34,Zones!$A:$B,2,0),"-",_xlfn.CONCAT(IF(K34<>"",VLOOKUP(K34,Desagregations!$A:$B,2,0),""),IF(L34<>"","_",""),IF(L34<>"",VLOOKUP(L34,Desagregations!$A:$B,2,0),""),IF(M34<>"","_",""),IF(M34<>"",VLOOKUP(M34,Desagregations!$A:$B,2,0),""),IF(N34<>"","_",""),IF(N34<>"",VLOOKUP(N34,Desagregations!$A:$B,2,0),""),IF(O34<>"","_",""),IF(O34<>"",VLOOKUP(O34,Desagregations!$A:$B,2,0),""),IF(P34<>"","_",""),IF(P34<>"",VLOOKUP(P34,Desagregations!$A:$B,2,0),"")),"-",VLOOKUP(D34,Unites!$A:$B,2,0),"-",VLOOKUP(E34,Sources!$A:$B,2,0),"-",VLOOKUP(F34,CommentaireValeurIndicateurs!$A:$B,2,0),"-",VLOOKUP(G34,NatureDonnees!$A:$B,2,0),"-",VLOOKUP(H34,Periodes!$A:$B,2,0)) -> 1278-1-6-4-16-3-3-25 | B34: Part de l'élevage dans le PIB | C34: NIGER | D34: % | E34: INS, 2024, comptes nationaux annuels (CNA) révisés 2015-2022 et provisoires 2023-2024 | F34: RAS | G34: Valeur de référence | H34: 2024 | I34: 8.97 | K34: Total
A35: =_xlfn.CONCAT(VLOOKUP(B35,Indicateurs!$A:$B,2,0),"-",VLOOKUP(C35,Zones!$A:$B,2,0),"-",_xlfn.CONCAT(IF(K35<>"",VLOOKUP(K35,Desagregations!$A:$B,2,0),""),IF(L35<>"","_",""),IF(L35<>"",VLOOKUP(L35,Desagregations!$A:$B,2,0),""),IF(M35<>"","_",""),IF(M35<>"",VLOOKUP(M35,Desagregations!$A:$B,2,0),""),IF(N35<>"","_",""),IF(N35<>"",VLOOKUP(N35,Desagregations!$A:$B,2,0),""),IF(O35<>"","_",""),IF(O35<>"",VLOOKUP(O35,Desagregations!$A:$B,2,0),""),IF(P35<>"","_",""),IF(P35<>"",VLOOKUP(P35,Desagregations!$A:$B,2,0),"")),"-",VLOOKUP(D35,Unites!$A:$B,2,0),"-",VLOOKUP(E35,Sources!$A:$B,2,0),"-",VLOOKUP(F35,CommentaireValeurIndicateurs!$A:$B,2,0),"-",VLOOKUP(G35,NatureDonnees!$A:$B,2,0),"-",VLOOKUP(H35,Periodes!$A:$B,2,0)) -> 1279-1-6-4-23-3-3-25 | B35: Indice d’accessibilité rurale | C35: NIGER | D35: % | E35: MEq, 2022, RAP | F35: RAS | G35: Valeur de référence | H35: 2024 | I35: 40.1 | K35: Total
A36: =_xlfn.CONCAT(VLOOKUP(B36,Indicateurs!$A:$B,2,0),"-",VLOOKUP(C36,Zones!$A:$B,2,0),"-",_xlfn.CONCAT(IF(K36<>"",VLOOKUP(K36,Desagregations!$A:$B,2,0),""),IF(L36<>"","_",""),IF(L36<>"",VLOOKUP(L36,Desagregations!$A:$B,2,0),""),IF(M36<>"","_",""),IF(M36<>"",VLOOKUP(M36,Desagregations!$A:$B,2,0),""),IF(N36<>"","_",""),IF(N36<>"",VLOOKUP(N36,Desagregations!$A:$B,2,0),""),IF(O36<>"","_",""),IF(O36<>"",VLOOKUP(O36,Desagregations!$A:$B,2,0),""),IF(P36<>"","_",""),IF(P36<>"",VLOOKUP(P36,Desagregations!$A:$B,2,0),"")),"-",VLOOKUP(D36,Unites!$A:$B,2,0),"-",VLOOKUP(E36,Sources!$A:$B,2,0),"-",VLOOKUP(F36,CommentaireValeurIndicateurs!$A:$B,2,0),"-",VLOOKUP(G36,NatureDonnees!$A:$B,2,0),"-",VLOOKUP(H36,Periodes!$A:$B,2,0)) -> 1280-1-6-4-24-3-3-23 | B36: Taux d’écoulement des produits agricoles entre le Niger et le reste du Monde | C36: NIGER | D36: % | E36: INS, 2023, Bulletin des statistiques du commerce extérieur | F36: RAS | G36: Valeur de référence | H36: 2022 | I36: 14.6 | K36: Total
A37: =_xlfn.CONCAT(VLOOKUP(B37,Indicateurs!$A:$B,2,0),"-",VLOOKUP(C37,Zones!$A:$B,2,0),"-",_xlfn.CONCAT(IF(K37<>"",VLOOKUP(K37,Desagregations!$A:$B,2,0),""),IF(L37<>"","_",""),IF(L37<>"",VLOOKUP(L37,Desagregations!$A:$B,2,0),""),IF(M37<>"","_",""),IF(M37<>"",VLOOKUP(M37,Desagregations!$A:$B,2,0),""),IF(N37<>"","_",""),IF(N37<>"",VLOOKUP(N37,Desagregations!$A:$B,2,0),""),IF(O37<>"","_",""),IF(O37<>"",VLOOKUP(O37,Desagregations!$A:$B,2,0),""),IF(P37<>"","_",""),IF(P37<>"",VLOOKUP(P37,Desagregations!$A:$B,2,0),"")),"-",VLOOKUP(D37,Unites!$A:$B,2,0),"-",VLOOKUP(E37,Sources!$A:$B,2,0),"-",VLOOKUP(F37,CommentaireValeurIndicateurs!$A:$B,2,0),"-",VLOOKUP(G37,NatureDonnees!$A:$B,2,0),"-",VLOOKUP(H37,Periodes!$A:$B,2,0)) -> 1281-1-6-4-25-3-3-25 | B37: Proportion des plateformes de commerces ayant une rubrique agricole | C37: NIGER | D37: % | E37: Ministère du Commerce et de l'Industrie | F37: RAS | G37: Valeur de référence | H37: 2024 | I37: 33 | K37: Total
A38: =_xlfn.CONCAT(VLOOKUP(B38,Indicateurs!$A:$B,2,0),"-",VLOOKUP(C38,Zones!$A:$B,2,0),"-",_xlfn.CONCAT(IF(K38<>"",VLOOKUP(K38,Desagregations!$A:$B,2,0),""),IF(L38<>"","_",""),IF(L38<>"",VLOOKUP(L38,Desagregations!$A:$B,2,0),""),IF(M38<>"","_",""),IF(M38<>"",VLOOKUP(M38,Desagregations!$A:$B,2,0),""),IF(N38<>"","_",""),IF(N38<>"",VLOOKUP(N38,Desagregations!$A:$B,2,0),""),IF(O38<>"","_",""),IF(O38<>"",VLOOKUP(O38,Desagregations!$A:$B,2,0),""),IF(P38<>"","_",""),IF(P38<>"",VLOOKUP(P38,Desagregations!$A:$B,2,0),"")),"-",VLOOKUP(D38,Unites!$A:$B,2,0),"-",VLOOKUP(E38,Sources!$A:$B,2,0),"-",VLOOKUP(F38,CommentaireValeurIndicateurs!$A:$B,2,0),"-",VLOOKUP(G38,NatureDonnees!$A:$B,2,0),"-",VLOOKUP(H38,Periodes!$A:$B,2,0)) -> 1282-1-6-4-25-3-3-25 | B38: Proportion d’unités agro-industrielles opérationnelles | C38: NIGER | D38: % | E38: Ministère du Commerce et de l'Industrie | F38: RAS | G38: Valeur de référence | H38: 2024 | I38: 59 | K38: Total
A39: =_xlfn.CONCAT(VLOOKUP(B39,Indicateurs!$A:$B,2,0),"-",VLOOKUP(C39,Zones!$A:$B,2,0),"-",_xlfn.CONCAT(IF(K39<>"",VLOOKUP(K39,Desagregations!$A:$B,2,0),""),IF(L39<>"","_",""),IF(L39<>"",VLOOKUP(L39,Desagregations!$A:$B,2,0),""),IF(M39<>"","_",""),IF(M39<>"",VLOOKUP(M39,Desagregations!$A:$B,2,0),""),IF(N39<>"","_",""),IF(N39<>"",VLOOKUP(N39,Desagregations!$A:$B,2,0),""),IF(O39<>"","_",""),IF(O39<>"",VLOOKUP(O39,Desagregations!$A:$B,2,0),""),IF(P39<>"","_",""),IF(P39<>"",VLOOKUP(P39,Desagregations!$A:$B,2,0),"")),"-",VLOOKUP(D39,Unites!$A:$B,2,0),"-",VLOOKUP(E39,Sources!$A:$B,2,0),"-",VLOOKUP(F39,CommentaireValeurIndicateurs!$A:$B,2,0),"-",VLOOKUP(G39,NatureDonnees!$A:$B,2,0),"-",VLOOKUP(H39,Periodes!$A:$B,2,0)) -> 1283-1-6-4-26-3-3-23 | B39: Part des activités minières dans le PIB (Uranate+Or) | C39: NIGER | D39: % | E39: INS, 2022, CEN | F39: RAS | G39: Valeur de référence | H39: 2022 | I39: 1.8 | K39: Total
A40: =_xlfn.CONCAT(VLOOKUP(B40,Indicateurs!$A:$B,2,0),"-",VLOOKUP(C40,Zones!$A:$B,2,0),"-",_xlfn.CONCAT(IF(K40<>"",VLOOKUP(K40,Desagregations!$A:$B,2,0),""),IF(L40<>"","_",""),IF(L40<>"",VLOOKUP(L40,Desagregations!$A:$B,2,0),""),IF(M40<>"","_",""),IF(M40<>"",VLOOKUP(M40,Desagregations!$A:$B,2,0),""),IF(N40<>"","_",""),IF(N40<>"",VLOOKUP(N40,Desagregations!$A:$B,2,0),""),IF(O40<>"","_",""),IF(O40<>"",VLOOKUP(O40,Desagregations!$A:$B,2,0),""),IF(P40<>"","_",""),IF(P40<>"",VLOOKUP(P40,Desagregations!$A:$B,2,0),"")),"-",VLOOKUP(D40,Unites!$A:$B,2,0),"-",VLOOKUP(E40,Sources!$A:$B,2,0),"-",VLOOKUP(F40,CommentaireValeurIndicateurs!$A:$B,2,0),"-",VLOOKUP(G40,NatureDonnees!$A:$B,2,0),"-",VLOOKUP(H40,Periodes!$A:$B,2,0)) -> 1284-1-6-4-26-3-3-23 | B40: Part des activités extractives pétrolières dans le PIB | C40: NIGER | D40: % | E40: INS, 2022, CEN | F40: RAS | G40: Valeur de référence | H40: 2022 | I40: 2.4 | K40: Total
... A56: =_xlfn.CONCAT(VLOOKUP(B56,Indicateurs!$A:$B,2,0),"-",VLOOKUP(C56,Zones!$A:$B,2,0),"-",_xlfn.CONCAT(IF(K56<>"",VLOOKUP(K56,Desagregations!$A:$B,2,0),""),IF(L56<>"","_",""),IF(L56<>"",VLOOKUP(L56,Desagregations!$A:$B,2,0),""),IF(M56<>"","_",""),IF(M56<>"",VLOOKUP(M56,Desagregations!$A:$B,2,0),""),IF(N56<>"","_",""),IF(N56<>"",VLOOKUP(N56,Desagregations!$A:$B,2,0),""),IF(O56<>"","_",""),IF(O56<>"",VLOOKUP(O56,Desagregations!$A:$B,2,0),""),IF(P56<>"","_",""),IF(P56<>"",VLOOKUP(P56,Desagregations!$A:$B,2,0),"")),"-",VLOOKUP(D56,Unites!$A:$B,2,0),"-",VLOOKUP(E56,Sources!$A:$B,2,0),"-",VLOOKUP(F56,CommentaireValeurIndicateurs!$A:$B,2,0),"-",VLOOKUP(G56,NatureDonnees!$A:$B,2,0),"-",VLOOKUP(H56,Periodes!$A:$B,2,0)) -> 1300-1-6-4-25-3-3-25 | B56: Taux de variation de brevets délivrés | C56: NIGER | D56: % | E56: Ministère du Commerce et de l'Industrie | F56: RAS | G56: Valeur de référence | H56: 2024 | I56: 20 | K56: Total
A57: =_xlfn.CONCAT(VLOOKUP(B57,Indicateurs!$A:$B,2,0),"-",VLOOKUP(C57,Zones!$A:$B,2,0),"-",_xlfn.CONCAT(IF(K57<>"",VLOOKUP(K57,Desagregations!$A:$B,2,0),""),IF(L57<>"","_",""),IF(L57<>"",VLOOKUP(L57,Desagregations!$A:$B,2,0),""),IF(M57<>"","_",""),IF(M57<>"",VLOOKUP(M57,Desagregations!$A:$B,2,0),""),IF(N57<>"","_",""),IF(N57<>"",VLOOKUP(N57,Desagregations!$A:$B,2,0),""),IF(O57<>"","_",""),IF(O57<>"",VLOOKUP(O57,Desagregations!$A:$B,2,0),""),IF(P57<>"","_",""),IF(P57<>"",VLOOKUP(P57,Desagregations!$A:$B,2,0),"")),"-",VLOOKUP(D57,Unites!$A:$B,2,0),"-",VLOOKUP(E57,Sources!$A:$B,2,0),"-",VLOOKUP(F57,CommentaireValeurIndicateurs!$A:$B,2,0),"-",VLOOKUP(G57,NatureDonnees!$A:$B,2,0),"-",VLOOKUP(H57,Periodes!$A:$B,2,0)) -> #N/A | B57: Dépense de recherche et développement en pourcentage du budget national | C57: NIGER | D57: % | E57: Ministère de l'Economie et des Finances | F57: RAS | G57: Valeur de référence | K57: Total
A58: =_xlfn.CONCAT(VLOOKUP(B58,Indicateurs!$A:$B,2,0),"-",VLOOKUP(C58,Zones!$A:$B,2,0),"-",_xlfn.CONCAT(IF(K58<>"",VLOOKUP(K58,Desagregations!$A:$B,2,0),""),IF(L58<>"","_",""),IF(L58<>"",VLOOKUP(L58,Desagregations!$A:$B,2,0),""),IF(M58<>"","_",""),IF(M58<>"",VLOOKUP(M58,Desagregations!$A:$B,2,0),""),IF(N58<>"","_",""),IF(N58<>"",VLOOKUP(N58,Desagregations!$A:$B,2,0),""),IF(O58<>"","_",""),IF(O58<>"",VLOOKUP(O58,Desagregations!$A:$B,2,0),""),IF(P58<>"","_",""),IF(P58<>"",VLOOKUP(P58,Desagregations!$A:$B,2,0),"")),"-",VLOOKUP(D58,Unites!$A:$B,2,0),"-",VLOOKUP(E58,Sources!$A:$B,2,0),"-",VLOOKUP(F58,CommentaireValeurIndicateurs!$A:$B,2,0),"-",VLOOKUP(G58,NatureDonnees!$A:$B,2,0),"-",VLOOKUP(H58,Periodes!$A:$B,2,0)) -> #N/A | B58: Proportion de projets de recherche financés | C58: NIGER | D58: % | E58: MESRIT | F58: RAS | G58: Valeur de référence | K58: Total
A59: =_xlfn.CONCAT(VLOOKUP(B59,Indicateurs!$A:$B,2,0),"-",VLOOKUP(C59,Zones!$A:$B,2,0),"-",_xlfn.CONCAT(IF(K59<>"",VLOOKUP(K59,Desagregations!$A:$B,2,0),""),IF(L59<>"","_",""),IF(L59<>"",VLOOKUP(L59,Desagregations!$A:$B,2,0),""),IF(M59<>"","_",""),IF(M59<>"",VLOOKUP(M59,Desagregations!$A:$B,2,0),""),IF(N59<>"","_",""),IF(N59<>"",VLOOKUP(N59,Desagregations!$A:$B,2,0),""),IF(O59<>"","_",""),IF(O59<>"",VLOOKUP(O59,Desagregations!$A:$B,2,0),""),IF(P59<>"","_",""),IF(P59<>"",VLOOKUP(P59,Desagregations!$A:$B,2,0),"")),"-",VLOOKUP(D59,Unites!$A:$B,2,0),"-",VLOOKUP(E59,Sources!$A:$B,2,0),"-",VLOOKUP(F59,CommentaireValeurIndicateurs!$A:$B,2,0),"-",VLOOKUP(G59,NatureDonnees!$A:$B,2,0),"-",VLOOKUP(H59,Periodes!$A:$B,2,0)) -> 1303-1-6-4-40-3-3-25 | B59: Taux de couverture sanitaire | C59: NIGER | D59: % | E59: Annuaire Statistique MSP, 2024 | F59: RAS | G59: Valeur de référence | H59: 2024 | I59: 56.59 | K59: Total
A60: =_xlfn.CONCAT(VLOOKUP(B60,Indicateurs!$A:$B,2,0),"-",VLOOKUP(C60,Zones!$A:$B,2,0),"-",_xlfn.CONCAT(IF(K60<>"",VLOOKUP(K60,Desagregations!$A:$B,2,0),""),IF(L60<>"","_",""),IF(L60<>"",VLOOKUP(L60,Desagregations!$A:$B,2,0),""),IF(M60<>"","_",""),IF(M60<>"",VLOOKUP(M60,Desagregations!$A:$B,2,0),""),IF(N60<>"","_",""),IF(N60<>"",VLOOKUP(N60,Desagregations!$A:$B,2,0),""),IF(O60<>"","_",""),IF(O60<>"",VLOOKUP(O60,Desagregations!$A:$B,2,0),""),IF(P60<>"","_",""),IF(P60<>"",VLOOKUP(P60,Desagregations!$A:$B,2,0),"")),"-",VLOOKUP(D60,Unites!$A:$B,2,0),"-",VLOOKUP(E60,Sources!$A:$B,2,0),"-",VLOOKUP(F60,CommentaireValeurIndicateurs!$A:$B,2,0),"-",VLOOKUP(G60,NatureDonnees!$A:$B,2,0),"-",VLOOKUP(H60,Periodes!$A:$B,2,0)) -> 1304-1-6-4-41-3-3-25 | B60: Taux d’accouchements assistés par un personnel qualifié | C60: NIGER | D60: % | E60: Annuaire Santé | F60: RAS | G60: Valeur de référence | H60: 2024 | I60: 47.42 | K60: Total
A61: =_xlfn.CONCAT(VLOOKUP(B61,Indicateurs!$A:$B,2,0),"-",VLOOKUP(C61,Zones!$A:$B,2,0),"-",_xlfn.CONCAT(IF(K61<>"",VLOOKUP(K61,Desagregations!$A:$B,2,0),""),IF(L61<>"","_",""),IF(L61<>"",VLOOKUP(L61,Desagregations!$A:$B,2,0),""),IF(M61<>"","_",""),IF(M61<>"",VLOOKUP(M61,Desagregations!$A:$B,2,0),""),IF(N61<>"","_",""),IF(N61<>"",VLOOKUP(N61,Desagregations!$A:$B,2,0),""),IF(O61<>"","_",""),IF(O61<>"",VLOOKUP(O61,Desagregations!$A:$B,2,0),""),IF(P61<>"","_",""),IF(P61<>"",VLOOKUP(P61,Desagregations!$A:$B,2,0),"")),"-",VLOOKUP(D61,Unites!$A:$B,2,0),"-",VLOOKUP(E61,Sources!$A:$B,2,0),"-",VLOOKUP(F61,CommentaireValeurIndicateurs!$A:$B,2,0),"-",VLOOKUP(G61,NatureDonnees!$A:$B,2,0),"-",VLOOKUP(H61,Periodes!$A:$B,2,0)) -> 1305-1-6-4-42-3-3-25 | B61: Proportion d’établissements de santé utilisant un dispositif adéquat de gestion des déchets d’activités de soins (GDAS) | C61: NIGER | D61: % | E61: Rapport d'évaluation, 2024, du PGDISS 2016-2020 | F61: RAS | G61: Valeur de référence | H61: 2024 | I61: 22.48 | K61: Total
A62: =_xlfn.CONCAT(VLOOKUP(B62,Indicateurs!$A:$B,2,0),"-",VLOOKUP(C62,Zones!$A:$B,2,0),"-",_xlfn.CONCAT(IF(K62<>"",VLOOKUP(K62,Desagregations!$A:$B,2,0),""),IF(L62<>"","_",""),IF(L62<>"",VLOOKUP(L62,Desagregations!$A:$B,2,0),""),IF(M62<>"","_",""),IF(M62<>"",VLOOKUP(M62,Desagregations!$A:$B,2,0),""),IF(N62<>"","_",""),IF(N62<>"",VLOOKUP(N62,Desagregations!$A:$B,2,0),""),IF(O62<>"","_",""),IF(O62<>"",VLOOKUP(O62,Desagregations!$A:$B,2,0),""),IF(P62<>"","_",""),IF(P62<>"",VLOOKUP(P62,Desagregations!$A:$B,2,0),"")),"-",VLOOKUP(D62,Unites!$A:$B,2,0),"-",VLOOKUP(E62,Sources!$A:$B,2,0),"-",VLOOKUP(F62,CommentaireValeurIndicateurs!$A:$B,2,0),"-",VLOOKUP(G62,NatureDonnees!$A:$B,2,0),"-",VLOOKUP(H62,Periodes!$A:$B,2,0)) -> 1306-1-6-4-43-3-3-23 | B62: Prévalence de la malnutrition aiguë globale chez les enfants de 6 à 59 mois | C62: NIGER | D62: % | E62: INS, 2022, Enquête SMART | F62: RAS | G62: Valeur de référence | H62: 2022 | I62: 12.2 | K62: Total
A63: =_xlfn.CONCAT(VLOOKUP(B63,Indicateurs!$A:$B,2,0),"-",VLOOKUP(C63,Zones!$A:$B,2,0),"-",_xlfn.CONCAT(IF(K63<>"",VLOOKUP(K63,Desagregations!$A:$B,2,0),""),IF(L63<>"","_",""),IF(L63<>"",VLOOKUP(L63,Desagregations!$A:$B,2,0),""),IF(M63<>"","_",""),IF(M63<>"",VLOOKUP(M63,Desagregations!$A:$B,2,0),""),IF(N63<>"","_",""),IF(N63<>"",VLOOKUP(N63,Desagregations!$A:$B,2,0),""),IF(O63<>"","_",""),IF(O63<>"",VLOOKUP(O63,Desagregations!$A:$B,2,0),""),IF(P63<>"","_",""),IF(P63<>"",VLOOKUP(P63,Desagregations!$A:$B,2,0),"")),"-",VLOOKUP(D63,Unites!$A:$B,2,0),"-",VLOOKUP(E63,Sources!$A:$B,2,0),"-",VLOOKUP(F63,CommentaireValeurIndicateurs!$A:$B,2,0),"-",VLOOKUP(G63,NatureDonnees!$A:$B,2,0),"-",VLOOKUP(H63,Periodes!$A:$B,2,0)) -> 1307-1-6-4-44-3-3-19 | B63: Pourcentage de personnes affectées assistées en vivres et biens non alimentaires | C63: NIGER | D63: % | E63: PAP/MAHGC | F63: RAS | G63: Valeur de référence | H63: 2018 | I63: 30 | K63: Total
A64: =_xlfn.CONCAT(VLOOKUP(B64,Indicateurs!$A:$B,2,0),"-",VLOOKUP(C64,Zones!$A:$B,2,0),"-",_xlfn.CONCAT(IF(K64<>"",VLOOKUP(K64,Desagregations!$A:$B,2,0),""),IF(L64<>"","_",""),IF(L64<>"",VLOOKUP(L64,Desagregations!$A:$B,2,0),""),IF(M64<>"","_",""),IF(M64<>"",VLOOKUP(M64,Desagregations!$A:$B,2,0),""),IF(N64<>"","_",""),IF(N64<>"",VLOOKUP(N64,Desagregations!$A:$B,2,0),""),IF(O64<>"","_",""),IF(O64<>"",VLOOKUP(O64,Desagregations!$A:$B,2,0),""),IF(P64<>"","_",""),IF(P64<>"",VLOOKUP(P64,Desagregations!$A:$B,2,0),"")),"-",VLOOKUP(D64,Unites!$A:$B,2,0),"-",VLOOKUP(E64,Sources!$A:$B,2,0),"-",VLOOKUP(F64,CommentaireValeurIndicateurs!$A:$B,2,0),"-",VLOOKUP(G64,NatureDonnees!$A:$B,2,0),"-",VLOOKUP(H64,Periodes!$A:$B,2,0)) -> 1308-1-6-4-4-3-3-22 | B64: Pourcentage des ménages en insécurité alimentaire bénéficiaires de transferts sociaux prévisibles caractérisés des pauvres | C64: NIGER | D64: % | E64: INS, 2021, EHCVM | F64: RAS | G64: Valeur de référence | H64: 2021 | I64: 52.6 | K64: Total
A65: =_xlfn.CONCAT(VLOOKUP(B65,Indicateurs!$A:$B,2,0),"-",VLOOKUP(C65,Zones!$A:$B,2,0),"-",_xlfn.CONCAT(IF(K65<>"",VLOOKUP(K65,Desagregations!$A:$B,2,0),""),IF(L65<>"","_",""),IF(L65<>"",VLOOKUP(L65,Desagregations!$A:$B,2,0),""),IF(M65<>"","_",""),IF(M65<>"",VLOOKUP(M65,Desagregations!$A:$B,2,0),""),IF(N65<>"","_",""),IF(N65<>"",VLOOKUP(N65,Desagregations!$A:$B,2,0),""),IF(O65<>"","_",""),IF(O65<>"",VLOOKUP(O65,Desagregations!$A:$B,2,0),""),IF(P65<>"","_",""),IF(P65<>"",VLOOKUP(P65,Desagregations!$A:$B,2,0),"")),"-",VLOOKUP(D65,Unites!$A:$B,2,0),"-",VLOOKUP(E65,Sources!$A:$B,2,0),"-",VLOOKUP(F65,CommentaireValeurIndicateurs!$A:$B,2,0),"-",VLOOKUP(G65,NatureDonnees!$A:$B,2,0),"-",VLOOKUP(H65,Periodes!$A:$B,2,0)) -> 1309-1-6-4-45-3-3-23 | B65: Taux de placement des jeunes | C65: NIGER | D65: % | E65: Rapport ANPE | F65: RAS | G65: Valeur de référence | H65: 2022 | I65: 19.5 | K65: Total
A66: =_xlfn.CONCAT(VLOOKUP(B66,Indicateurs!$A:$B,2,0),"-",VLOOKUP(C66,Zones!$A:$B,2,0),"-",_xlfn.CONCAT(IF(K66<>"",VLOOKUP(K66,Desagregations!$A:$B,2,0),""),IF(L66<>"","_",""),IF(L66<>"",VLOOKUP(L66,Desagregations!$A:$B,2,0),""),IF(M66<>"","_",""),IF(M66<>"",VLOOKUP(M66,Desagregations!$A:$B,2,0),""),IF(N66<>"","_",""),IF(N66<>"",VLOOKUP(N66,Desagregations!$A:$B,2,0),""),IF(O66<>"","_",""),IF(O66<>"",VLOOKUP(O66,Desagregations!$A:$B,2,0),""),IF(P66<>"","_",""),IF(P66<>"",VLOOKUP(P66,Desagregations!$A:$B,2,0),"")),"-",VLOOKUP(D66,Unites!$A:$B,2,0),"-",VLOOKUP(E66,Sources!$A:$B,2,0),"-",VLOOKUP(F66,CommentaireValeurIndicateurs!$A:$B,2,0),"-",VLOOKUP(G66,NatureDonnees!$A:$B,2,0),"-",VLOOKUP(H66,Periodes!$A:$B,2,0)) -> 1310-1-6-4-4-3-3-22 | B66: Taux de chômage des jeunes (15 à 34 ans) | C66: NIGER | D66: % | E66: INS, 2021, EHCVM | F66: RAS | G66: Valeur de référence | H66: 2021 | I66: 10.1 | K66: Total
A67: =_xlfn.CONCAT(VLOOKUP(B67,Indicateurs!$A:$B,2,0),"-",VLOOKUP(C67,Zones!$A:$B,2,0),"-",_xlfn.CONCAT(IF(K67<>"",VLOOKUP(K67,Desagregations!$A:$B,2,0),""),IF(L67<>"","_",""),IF(L67<>"",VLOOKUP(L67,Desagregations!$A:$B,2,0),""),IF(M67<>"","_",""),IF(M67<>"",VLOOKUP(M67,Desagregations!$A:$B,2,0),""),IF(N67<>"","_",""),IF(N67<>"",VLOOKUP(N67,Desagregations!$A:$B,2,0),""),IF(O67<>"","_",""),IF(O67<>"",VLOOKUP(O67,Desagregations!$A:$B,2,0),""),IF(P67<>"","_",""),IF(P67<>"",VLOOKUP(P67,Desagregations!$A:$B,2,0),"")),"-",VLOOKUP(D67,Unites!$A:$B,2,0),"-",VLOOKUP(E67,Sources!$A:$B,2,0),"-",VLOOKUP(F67,CommentaireValeurIndicateurs!$A:$B,2,0),"-",VLOOKUP(G67,NatureDonnees!$A:$B,2,0),"-",VLOOKUP(H67,Periodes!$A:$B,2,0)) -> 1311-1-6-4-46-3-3-25 | B67: Taux de couverture géographique en eau potable en milieu rural | C67: NIGER | D67: % | E67: Rapport sur les indicateurs MH/A | F67: RAS | G67: Valeur de référence | H67: 2024 | I67: 74.2 | K67: Total
A68: =_xlfn.CONCAT(VLOOKUP(B68,Indicateurs!$A:$B,2,0),"-",VLOOKUP(C68,Zones!$A:$B,2,0),"-",_xlfn.CONCAT(IF(K68<>"",VLOOKUP(K68,Desagregations!$A:$B,2,0),""),IF(L68<>"","_",""),IF(L68<>"",VLOOKUP(L68,Desagregations!$A:$B,2,0),""),IF(M68<>"","_",""),IF(M68<>"",VLOOKUP(M68,Desagregations!$A:$B,2,0),""),IF(N68<>"","_",""),IF(N68<>"",VLOOKUP(N68,Desagregations!$A:$B,2,0),""),IF(O68<>"","_",""),IF(O68<>"",VLOOKUP(O68,Desagregations!$A:$B,2,0),""),IF(P68<>"","_",""),IF(P68<>"",VLOOKUP(P68,Desagregations!$A:$B,2,0),"")),"-",VLOOKUP(D68,Unites!$A:$B,2,0),"-",VLOOKUP(E68,Sources!$A:$B,2,0),"-",VLOOKUP(F68,CommentaireValeurIndicateurs!$A:$B,2,0),"-",VLOOKUP(G68,NatureDonnees!$A:$B,2,0),"-",VLOOKUP(H68,Periodes!$A:$B,2,0)) -> 1312-1-6-4-46-3-3-25 | B68: Taux d’accès théorique à l’eau potable en milieu rural | C68: NIGER | D68: % | E68: Rapport sur les indicateurs MH/A | F68: RAS | G68: Valeur de référence | H68: 2024 | I68: 49.69 | K68: Total
...
